<?xml version="1.0" ?>
<robot name="leg_design_simplified">

  <!-- Root link -->
  <link name="body">
    <inertial>
      <mass value="3.0"/>
      <inertia ixx="0.1" iyy="0.1" izz="0.1"/>
      <origin xyz="0 0 0" />
    </inertial>
    <visual>
      <geometry>
        <mesh filename="body_parts\body\root_skeleton.stl"/>
      </geometry>
      <origin xyz="0 0 0" />
    </visual>
    <collision>
      <geometry>
        <mesh filename="body_parts\body\root_skeleton.stl"/>
      </geometry>
      <origin xyz="0 0 0"/>
    </collision>
  </link>

  <!-- Hip top right -->
  <link name="hip_top_right">
    <visual>
      <geometry>
        <mesh filename="body_parts\leg_front_right\front_right_hip.stl"/>
      </geometry>
    </visual>
    <collision>
      <geometry>
        <mesh filename="body_parts\leg_front_right\front_right_hip.stl"/>
      </geometry>
    </collision>
    <inertial>
      <mass value="0.005"/>
      <inertia ixx="1e-07" iyy="1e-07" izz="2e-07" ixy="0" ixz="0" iyz="0"/>
      <origin xyz="0 0 0"/>
    </inertial>
  </link>

  <!-- Hip top left -->
  <link name="hip_top_left">
    <visual>
      <geometry>
        <mesh filename="body_parts\leg_front_left\front_left_hip.stl"/>
      </geometry>
    </visual>
    <collision>
      <geometry>
        <mesh filename="body_parts\leg_front_left\front_left_hip.stl"/>
      </geometry>
    </collision>
    <inertial>
      <mass value="0.005"/>
      <inertia ixx="1e-07" iyy="1e-07" izz="2e-07" ixy="0" ixz="0" iyz="0"/>
      <origin xyz="0 0 0"/>
    </inertial>
  </link>
  
  <!-- Hip down right -->
  <link name="hip_down_right">
    <visual>
      <geometry>
        <mesh filename="body_parts\leg_back_right\back_right_hip.stl"/>
      </geometry>
    </visual>
    <collision>
      <geometry>
        <mesh filename="body_parts\leg_back_right\back_right_hip.stl"/>
      </geometry>
    </collision>
    <inertial>
      <mass value="0.005"/>
      <inertia ixx="1e-07" iyy="1e-07" izz="2e-07" ixy="0" ixz="0" iyz="0"/>
      <origin xyz="0 0 0"/>
    </inertial>
  </link>

  <!-- Hip down left -->
  <link name="hip_down_left">
    <visual>
      <geometry>
        <mesh filename="body_parts\leg_back_left\back_left_hip.stl"/>
      </geometry>
    </visual>
    <collision>
      <geometry>
        <mesh filename="body_parts\leg_back_left\back_left_hip.stl"/>
      </geometry>
    </collision>
    <inertial>
      <mass value="0.005"/>
      <inertia ixx="1e-07" iyy="1e-07" izz="2e-07" ixy="0" ixz="0" iyz="0"/>
      <origin xyz="0 0 0"/>
    </inertial>
  </link>

  <!-- Fibula branch -->
  <link name="fibula_top_right">
    <visual>
      <geometry>
        <box size="0.15 0.02 0.01"/>
      </geometry>
    </visual>
    <collision>
      <geometry>
        <box size="0.15 0.02 0.01"/>
      </geometry>
    </collision>
    <inertial>
      <mass value="0.017"/>
      <inertia ixx="0.00029" iyy="0.00031" izz="0.00059" ixy="0" ixz="0" iyz="0"/>
      <origin xyz="0 0 0"/>
    </inertial>
  </link>

  <!-- Tibia (main leg link) -->
  <link name="tibia_top_right">
    <visual>
      <geometry>
        <box size="0.16 0.02 0.015"/>
      </geometry>
    </visual>
    <collision>
      <geometry>
        <box size="0.16 0.02 0.015"/>
      </geometry>
    </collision>
    <inertial>
      <mass value="0.017"/>
      <inertia ixx="3.8e-05" iyy="3.8e-05" izz="7.7e-05" ixy="0" ixz="0" iyz="0"/>
      <origin xyz="0.106 -0.155 0.172"/>
    </inertial>
  </link>

  <!-- Small link -->
  <link name="small_link_top_right">
    <visual>
      <geometry>
        <box size="0.03 0.02 0.005"/>
      </geometry>
    </visual>
    <collision>
      <geometry>
        <box size="0.03 0.02 0.005"/>
      </geometry>
    </collision>
    <inertial>
      <mass value="0.002"/>
      <inertia ixx="1.6e-07" iyy="1.8e-07" izz="3.4e-07" ixy="0" ixz="0" iyz="0"/>
      <origin xyz="0.063 -0.013 0.171"/>
    </inertial>
  </link>

  <!-- Servo housing -->
  <link name="servo_housing_top_right">
    <visual>
      <geometry>
        <box size="0.06 0.05 0.01"/>
      </geometry>
    </visual>
    <collision>
      <geometry>
        <box size="0.06 0.05 0.01"/>
      </geometry>
    </collision>
    <inertial>
      <mass value="0.022"/>
      <inertia ixx="2e-07" iyy="2e-07" izz="3.4e-07" ixy="0" ixz="0" iyz="0"/>
      <origin xyz="0.063 -0.013 0.171"/>
    </inertial>
  </link>

  <!-- Mirrored servo extension branch -->
  <link name="mirrored_servo_extension_top_right">
    <visual>
      <geometry>
        <box size="0.06 0.05 0.01"/>
      </geometry>
    </visual>
    <collision>
      <geometry>
        <box size="0.06 0.05 0.01"/>
      </geometry>
    </collision>
    <inertial>
      <mass value="0.022"/>
      <inertia ixx="1e-08" iyy="1e-08" izz="1e-08" ixy="0" ixz="0" iyz="0"/>
      <origin xyz="0.124 0.038 0.132"/>
    </inertial>
  </link>

  <!-- Servo extension horn mock 2 (fibula branch) -->
  <link name="servo_extension_horn_mock_2_top_right">
    <visual>
      <geometry>
        <box size="0.068 0.012 0.006"/>
      </geometry>
    </visual>
    <collision>
      <geometry>
        <box size="0.068 0.012 0.006"/>
      </geometry>
    </collision>
    <inertial>
      <origin xyz="0.153 -0.002 0.164"/>
      <mass value="0.005"/>
      <inertia 
        ixx="1.904e-08" 
        iyy="2.786e-08" 
        izz="4.608e-08" 
        ixy="2.050e-08" 
        ixz="2.489e-10" 
        iyz="-2.222e-10"/>
    </inertial>
  </link>

  <!-- Servo extension horn mock 1 (tibia branch) -->
  <link name="servo_extension_horn_mock_1_top_right">
    <visual>
      <geometry>
        <box size="0.068 0.012 0.006"/>
      </geometry>
    </visual>
    <collision>
      <geometry>
        <box size="0.068 0.012 0.006"/>
      </geometry>
    </collision>
    <inertial>
      <origin xyz="0.153 -0.002 0.164"/>
      <mass value="0.005"/>
      <inertia 
        ixx="1.904e-08" 
        iyy="2.786e-08" 
        izz="4.608e-08" 
        ixy="2.050e-08" 
        ixz="2.489e-10" 
        iyz="-2.222e-10"/>
    </inertial>
  </link>

  <!-- Large linkage (tibia branch) -->
  <link name="large_link_top_right">
    <visual>
      <geometry>
        <box size="0.151 0.02 0.018"/>
      </geometry>
    </visual>
    <collision>
      <geometry>
        <box size="0.151 0.02 0.018"/>
      </geometry>
    </collision>
    <inertial>
      <mass value="0.017"/>
      <origin xyz="0 0 0"/>
      <inertia 
        ixx="1.029e-06" iyy="3.297e-05" izz="3.306e-05"
        ixy="0.0" ixz="0.0" iyz="0.0"/>
    </inertial>
  </link>

  <!-- Joints -->

  <!-- Attach servo housing to the body (main root) -->
  <joint name="servo_on_main" type="fixed">
    <parent link="body"/>
    <child link="servo_housing_top_right"/>
    <origin xyz="0.453 0.213 0.121" rpy="0 0 0"/>
  </joint>

  <!-- Attach mirrored servo extension to servo housing -->
  <joint name="mirrored_servo_extension_joint_top_right" type="fixed">
    <parent link="servo_housing_top_right"/>
    <child link="mirrored_servo_extension_top_right"/>
    <origin xyz="0.124 0.038 0.132" rpy="0 0 0"/>
  </joint>

  <!-- Attach servo extension horn mock 2 to servo housing (fibula branch) -->
  <joint name="servo_extend_on_servo_hous_2" type="revolute">
    <parent link="servo_housing_top_right"/>
    <child link="servo_extension_horn_mock_2_top_right"/>
    <origin xyz="0.03 0 0" rpy="0 0 0"/>
    <axis xyz="0 0 1"/>
    <limit effort="0" velocity="0"/>
    <dynamics damping="0.1" friction="0.1"/>
  </joint>

  <!-- Attach servo extension horn mock 1 to servo housing (tibia branch) -->
  <joint name="servo_extend_on_servo_hous_1" type="revolute">
    <parent link="servo_housing_top_right"/>
    <child link="servo_extension_horn_mock_1_top_right"/>
    <origin xyz="-0.03 0 0" rpy="0 0 0"/>
    <axis xyz="0 0 1"/>
    <limit effort="0" velocity="0"/>
    <dynamics damping="0.1" friction="0.1"/>
  </joint>

  <!-- Connect fibula to servo extension horn mock 2 -->
  <joint name="fibula_on_servo_extend_mock_2" type="revolute">
    <parent link="servo_extension_horn_mock_2_top_right"/>
    <child link="fibula_top_right"/>
    <origin xyz="0.034 0 0" rpy="0 0 0"/>
    <axis xyz="1 0 0"/>
    <limit effort="0" velocity="0"/>
    <dynamics damping="0.1" friction="0.1"/>
  </joint>

  <!-- Connect small link to servo extension horn mock 1 -->
  <joint name="small_link_on_servo_extension_mock_1" type="revolute">
    <parent link="servo_extension_horn_mock_1_top_right"/>
    <child link="small_link_top_right"/>
    <origin xyz="0.034 0 0" rpy="0 0 0"/>
    <axis xyz="1 0 0"/>
    <limit effort="0" velocity="0"/>
    <dynamics damping="0.1" friction="0.1"/>
  </joint>

  <!-- Connect large link to small link (tibia branch) -->
  <joint name="large_link_on_small_link" type="revolute">
    <parent link="small_link_top_right"/>
    <child link="large_link_top_right"/>
    <origin xyz="0.0755 0 0" rpy="0 0 0"/>
    <axis xyz="1 0 0"/>
    <limit effort="0" velocity="0"/>
    <dynamics damping="0.1" friction="0.1"/>
  </joint>

  <!-- Attach tibia to large link -->
  <joint name="tibia_on_large_link" type="revolute">
    <parent link="large_link_top_right"/>
    <child link="tibia_top_right"/>
    <origin xyz="0.151 -0.155 0.172" rpy="0 0 0"/>
    <axis xyz="1 0 0"/>
    <limit effort="0" velocity="0"/>
    <dynamics damping="0.1" friction="0.1"/>
  </joint>

</robot>
