<?xml version="1.0" ?>
<mujoco model="simple_quadruped">
  <compiler angle="radian" coordinate="local"/>
  <option gravity="0 0 -9.81"/>

  <!-- make the body free to translate & rotate -->
  <worldbody>
    <body name="base" pos="0 0 0.3">
      <freejoint name="root_joint"/>

      <!-- Main torso geom -->
      <geom name="body_geom" type="box" size="0.2 0.1 0.05" pos="0 0 0"
            mass="5.0"/>

      <!-- FRONT LEFT LEG -->
      <body name="hip_fl" pos="0.15 0.1 -0.025">
        <joint name="knee_joint_fl" type="hinge" axis="0 1 0" pos="0 0 0"
               range="-1.57 1.57" damping="1"/>
        <geom name="upper_leg_fl" type="cylinder" size="0.02 0.05" pos="0 0 -0.05"/>

        <body name="ankle_fl" pos="0 0 -0.1">
          <joint name="ankle_joint_fl" type="hinge" axis="0 1 0" pos="0 0 0"
                 range="-1.57 1.57" damping="1"/>
          <geom name="lower_leg_fl" type="cylinder" size="0.02 0.05" pos="0 0 -0.05"/>
        </body>
      </body>

      <!-- FRONT RIGHT LEG -->
      <body name="hip_fr" pos="0.15 -0.1 -0.025">
        <joint name="knee_joint_fr" type="hinge" axis="0 1 0" pos="0 0 0"
               range="-1.57 1.57" damping="1"/>
        <geom name="upper_leg_fr" type="cylinder" size="0.02 0.05" pos="0 0 -0.05"/>

        <body name="ankle_fr" pos="0 0 -0.1">
          <joint name="ankle_joint_fr" type="hinge" axis="0 1 0" pos="0 0 0"
                 range="-1.57 1.57" damping="1"/>
          <geom name="lower_leg_fr" type="cylinder" size="0.02 0.05" pos="0 0 -0.05"/>
        </body>
      </body>

      <!-- REAR LEFT LEG -->
      <body name="hip_rl" pos="-0.15 0.1 -0.025">
        <joint name="knee_joint_rl" type="hinge" axis="0 1 0" pos="0 0 0"
               range="-1.57 1.57" damping="1"/>
        <geom name="upper_leg_rl" type="cylinder" size="0.02 0.05" pos="0 0 -0.05"/>

        <body name="ankle_rl" pos="0 0 -0.1">
          <joint name="ankle_joint_rl" type="hinge" axis="0 1 0" pos="0 0 0"
                 range="-1.57 1.57" damping="1"/>
          <geom name="lower_leg_rl" type="cylinder" size="0.02 0.05" pos="0 0 -0.05"/>
        </body>
      </body>

      <!-- REAR RIGHT LEG -->
      <body name="hip_rr" pos="-0.15 -0.1 -0.025">
        <joint name="knee_joint_rr" type="hinge" axis="0 1 0" pos="0 0 0"
               range="-1.57 1.57" damping="1"/>
        <geom name="upper_leg_rr" type="cylinder" size="0.02 0.05" pos="0 0 -0.05"/>

        <body name="ankle_rr" pos="0 0 -0.1">
          <joint name="ankle_joint_rr" type="hinge" axis="0 1 0" pos="0 0 0"
                 range="-1.57 1.57" damping="1"/>
          <geom name="lower_leg_rr" type="cylinder" size="0.02 0.05" pos="0 0 -0.05"/>
        </body>
      </body>

    </body>
  </worldbody>
  
  <asset>
    <!-- optional checkerboard texture -->
    <texture name="checker" type="2d" builtin="checker"
             rgb1="0.2 0.3 0.4" rgb2="1 1 1"
             width="512" height="512"/>
    <material name="ground" texture="checker" texrepeat="10 10" reflectance="0.1"/>
  </asset>

  <worldbody>
    <!-- add this geom for your floor -->
    <geom name="floor" type="plane" pos="0 0 0" size="10 10 0.1"
          material="ground"/>

    <!-- your existing quadruped (root body) goes here -->
    <body name="torso" pos="0 0 0.5">
      <!-- ... -->
    </body>
  </worldbody>

  <!-- actuators -->
  <actuator>
    <motor name="motor_knee_fl"  joint="knee_joint_fl"  gear="1"/>
    <motor name="motor_ankle_fl" joint="ankle_joint_fl" gear="1"/>
    <motor name="motor_knee_fr"  joint="knee_joint_fr"  gear="1"/>
    <motor name="motor_ankle_fr" joint="ankle_joint_fr" gear="1"/>
    <motor name="motor_knee_rl"  joint="knee_joint_rl"  gear="1"/>
    <motor name="motor_ankle_rl" joint="ankle_joint_rl" gear="1"/>
    <motor name="motor_knee_rr"  joint="knee_joint_rr"  gear="1"/>
    <motor name="motor_ankle_rr" joint="ankle_joint_rr" gear="1"/>
  </actuator>
</mujoco>
